Workbook
Name \i: #REF!
Name \i: #REF!
Name \i: #REF!
Name \i: #REF!
Name a: #REF!
Name a: #REF!
Name a: #REF!
Name a: #REF!
Name ADF: #REF!
Name ADF: #REF!
Name ADF: #REF!
Name ADF: #REF!
Name DF: #REF!
Name DF: #REF!
Name DF: #REF!
Name DF: #REF!
Name ISSQN: #REF!
Name ISSQN: #REF!
Name ISSQN: #REF!
Name ISSQN: #REF!
Name k: '[1]Tab. Consultoria Jan-11'!#REF!
Name k: '[1]Tab. Consultoria Jan-11'!#REF!
Name k: '[1]Tab. Consultoria Jan-11'!#REF!
Name k: '[1]Tab. Consultoria Jan-11'!#REF!
Name MO: #REF!
Name MO: #REF!
Name MO: #REF!
Name MO: #REF!
Name MOB: #REF!
Name MOB: #REF!
Name MOB: #REF!
Name MOB: #REF!
Name MOD: #REF!
Name MOD: #REF!
Name MOD: #REF!
Name MOD: #REF!
Name p: #REF!
Name p: #REF!
Name p: #REF!
Name p: #REF!
Name ref: '[1]Tab. Consultoria Jan-11'!#REF!
Name ref: '[1]Tab. Consultoria Jan-11'!#REF!
Name ref: '[1]Tab. Consultoria Jan-11'!#REF!
Name ref: '[1]Tab. Consultoria Jan-11'!#REF!
Name SICRO_AV: [2]SICRO_AV!$A$6:$N$22
Name SICRO_BAR: [2]SICRO!$A$6:$N$22
Name SICRO_R: [2]SICRO_R!$A$6:$N$22
Name vd: #REF!
Name vd: #REF!
Name vd: #REF!
Name vd: #REF!

Sheet Tabela DNIT Janeiro_2026
A1: Tabela Consultoria DNIT - janeiro/2026
A2: Categoria | B2: Unid. | C2: Código | D2: Salário
A3: Advogado júnior | B3: Mês | C3: P8001 | D3: 5061.91
A4: Administrador júnior | B4: Mês | C4: P8173 | D4: 3695.94
A5: Administrador pleno | B5: Mês | C5: P8174 | D5: 4927.92
A6: Administrador sênior | B6: Mês | C6: P8175 | D6: 8887.1
A7: Advogado pleno | B7: Mês | C7: P8002 | D7: 6749.21
A8: Advogado sênior | B8: Mês | C8: P8003 | D8: 11925.76
A9: Agente local | B9: Mês | C9: P8090 | D9: 1917.88
A10: Analista de desenvolvimento de sistemas júnior | B10: Mês | C10: P8007 | D10: 4278.65
A11: Analista de desenvolvimento de sistemas pleno | B11: Mês | C11: P8008 | D11: 5704.87
A12: Analista de desenvolvimento de sistemas sênior | B12: Mês | C12: P8009 | D12: 10201.29
A13: Antropólogo júnior | B13: Mês | C13: P8186 | D13: 3523.08
A14: Antropólogo pleno | B14: Mês | C14: P8187 | D14: 4697.44
... A107: Bolsista de Mestrado - 30 horas | B107: Mês | C107: BM30 | D107: 3350
A108: Bolsista de Mestrado - 20 horas | B108: Mês | C108: BM20 | D108: =2100+100 -> 2200
A109: Bolsista de Graduação - 30 horas | B109: Mês | C109: BG30 | D109: 1625
A110: Bolsista de Graduação - 20 horas | B110: Mês | C110: BG20 | D110: =950+100 -> 1050

Sheet Orçamento-Ação1
B1: Qtde | C1: DNIT - jul 25 | E1: Carga Horária Mensal | F1: Valor Mensal | G1: Meses | H1: Vínculo | I1: Encargos | J1: Total (R$)
C2: Ref. | D2: Valor (R$) | L2: UFSC | M2: Externo | N2: adm
A3: Coordenador do Termo de Execução Descentralizada | B3: 1 | C3: BC | D3: =VLOOKUP(C3,'[3]Tabela DNIT Janeiro_2026'!$C$3:$D$110,2,FALSE) -> 5000 | E3: 5 | F3: =(D3)*B3/2 -> 2500 | G3: 30 | H3: Bolsa | I3: 0 | J3: =F3*G3*(1+I3) -> 75000 | K3: 240000 | L3: =IF(H3="bolsa",B3,"-") -> 1 | M3: =IF(H3<>"bolsa",B3,"-") -> - | N3: =(J18+J19+J17)/J77 -> 0.042182868
A4: Engenheiro Coordenador | B4: 1 | C4: P8061 | D4: =VLOOKUP(C4,'[3]Tabela DNIT Janeiro_2026'!$C$3:$D$110,2,FALSE) -> 19804.31 | E4: 50 | F4: =(D4/200)*E4*B4 -> 4951.0775 | G4: 30 | H4: CLT | I4: 0.8404 | J4: =F4*G4*(1+I4) -> 273358.89 | K4: 374483.48 | L4: =IF(H4="bolsa",B4,"-") -> - | M4: =IF(H4<>"bolsa",B4,"-") -> 1
A5: Engenheiro Técnico Responsável (civil) | B5: 1 | C5: P8067 | D5: =VLOOKUP(C5,'[3]Tabela DNIT Janeiro_2026'!$C$3:$D$110,2,FALSE) -> 17274.58 | E5: 100 | F5: =(D5/200)*E5*B5 -> 8637.29 | G5: 30 | H5: CLT | I5: 0.8404 | J5: =F5*G5*(1+I5) -> 476882.06 | K5: 561589.19 | L5: =IF(H5="bolsa",B5,"-") -> - | M5: =IF(H5<>"bolsa",B5,"-") -> 1
A6: Engenheiro de Projetos sênior (civil) | B6: 1 | C6: P8067 | D6: =VLOOKUP(C6,'[3]Tabela DNIT Janeiro_2026'!$C$3:$D$110,2,FALSE) -> 17274.58 | E6: 100 | F6: =(D6/200)*E6*B6 -> 8637.29 | G6: 30 | H6: CLT | I6: 0.8404 | J6: =F6*G6*(1+I6) -> 476882.06 | K6: 561589.19 | L6: =IF(H6="bolsa",B6,"-") -> - | M6: =IF(H6<>"bolsa",B6,"-") -> 1
A7: Engenheiro de Projetos junior (civil) | B7: 2 | C7: P8065 | D7: =VLOOKUP(C7,'[3]Tabela DNIT Janeiro_2026'!$C$3:$D$110,2,FALSE) -> 12443.57 | E7: 200 | F7: =(D7/200)*E7*B7 -> 24887.14 | G7: 30 | H7: CLT | I7: 0.8404 | J7: =F7*G7*(1+I7) -> 1374068.8 | K7: 961848.14 | L7: =IF(H7="bolsa",B7,"-") -> - | M7: =IF(H7<>"bolsa",B7,"-") -> 2
A8: Engenheiro de Projetos júnior (mecatrônico) | B8: 1 | C8: P8065 | D8: =VLOOKUP(C8,'[3]Tabela DNIT Janeiro_2026'!$C$3:$D$110,2,FALSE) -> 12443.57 | E8: 100 | F8: =(D8/200)*E8*B8 -> 6221.785 | G8: 30 | H8: CLT | I8: 0.8404 | J8: =F8*G8*(1+I8) -> 343517.19 | K8: 687034.39 | L8: =IF(H8="bolsa",B8,"-") -> - | M8: =IF(H8<>"bolsa",B8,"-") -> 1
A9: Analista de Banco de Dados | B9: 1 | C9: P8009 | D9: =VLOOKUP(C9,'[3]Tabela DNIT Janeiro_2026'!$C$3:$D$110,2,FALSE) -> 10201.29 | E9: 200 | F9: =(D9/200)*E9*B9 -> 10201.29 | G9: 24 | H9: CLT | I9: 0.8404 | J9: =F9*G9*(1+I9) -> 450586.9 | K9: 297663.1 | L9: =IF(H9="bolsa",B9,"-") -> - | M9: =IF(H9<>"bolsa",B9,"-") -> 1
A10: Desenvolvedor Fullstack Sênior | B10: 1 | C10: P8009 | D10: =VLOOKUP(C10,'[4]Tabela DNIT Janeiro_2026'!$C$3:$D$110,2,FALSE) -> 10201.29 | E10: 100 | F10: =B10*(D10/200)*E10 -> 5100.645 | G10: 24 | H10: CLT | I10: 0.8404 | J10: =F10*G10*(1+I10) -> 225293.45 | K10: 432000 | L10: =IF(H12="bolsa",B12,"-") -> 3 | M10: =IF(H12<>"bolsa",B12,"-") -> -
A11: Desenvolvedor Front end Sênior | B11: 1 | C11: P8009 | D11: =VLOOKUP(C11,'[4]Tabela DNIT Janeiro_2026'!$C$3:$D$110,2,FALSE) -> 10201.29 | E11: 100 | F11: =B11*(D11/200)*E11 -> 5100.645 | G11: 24 | H11: CLT | I11: 0.8404 | J11: =F11*G11*(1+I11) -> 225293.45 | K11: 226800 | L11: =IF(H13="bolsa",B13,"-") -> 6 | M11: =IF(H13<>"bolsa",B13,"-") -> -
A12: Bolsa de Professor | B12: 3 | C12: BP | D12: =VLOOKUP(C12,'[3]Tabela DNIT Janeiro_2026'!$C$3:$D$110,2,FALSE) -> 3000 | E12: 100 | F12: =(D12/200)*E12*B12 -> 4500 | G12: 30 | H12: Bolsa | I12: 0 | J12: =F12*G12*(1+I12) -> 135000 | K12: 158400 | L12: =IF(H14="bolsa",B14,"-") -> 2 | M12: =IF(H14<>"bolsa",B14,"-") -> -
A13: Bolsista de Graduação | B13: 6 | C13: BG20 | D13: =VLOOKUP(C13,'[3]Tabela DNIT Janeiro_2026'!$C$3:$D$110,2,FALSE) -> 1050 | E13: 100 | F13: =(D13/200)*E13*B13 -> 3150 | G13: 30 | H13: Bolsa | I13: 0 | J13: =F13*G13*(1+I13) -> 94500 | K13: 230400 | L13: =IF(H15="bolsa",B15,"-") -> 2 | M13: =IF(H15<>"bolsa",B15,"-") -> -
A14: Bolsista de Mestrado | B14: 2 | C14: BM20 | D14: =VLOOKUP(C14,'[3]Tabela DNIT Janeiro_2026'!$C$3:$D$110,2,FALSE) -> 2200 | E14: 100 | F14: =(D14/200)*E14*B14 -> 2200 | G14: 30 | H14: Bolsa | I14: 0 | J14: =F14*G14*(1+I14) -> 66000 | K14: 59939.251 | L14: =IF(H16="bolsa",B16,"-") -> - | M14: =IF(H16<>"bolsa",B16,"-") -> 1
A15: Bolsista de Doutorado | B15: 2 | C15: BD20 | D15: =VLOOKUP(C15,'[3]Tabela DNIT Janeiro_2026'!$C$3:$D$110,2,FALSE) -> 3200 | E15: 100 | F15: =(D15/200)*E15*B15 -> 3200 | G15: 30 | H15: Bolsa | I15: 0 | J15: =F15*G15*(1+I15) -> 96000 | K15: 293013.77 | L15: =IF(H17="bolsa",B17,"-") -> - | M15: =IF(H17<>"bolsa",B17,"-") -> 1
A16: Redator/Revisor técnico | B16: 1 | C16: P8131 | D16: =VLOOKUP(C16,'[3]Tabela DNIT Janeiro_2026'!$C$3:$D$110,2,FALSE) -> 4110.73 | E16: 50 | F16: =(D16/200)*E16*B16 -> 1027.6825 | G16: 30 | H16: CLT | I16: 0.8404 | J16: =F16*G16*(1+I16) -> 56740.406 | K16: 764579.31 | L16: =IF(H18="bolsa",B18,"-") -> - | M16: =IF(H18<>"bolsa",B18,"-") -> 1
A17: Assessoria técnica especializada | B17: 1 | C17: P8060 | D17: =VLOOKUP(C17,'[3]Tabela DNIT Janeiro_2026'!$C$3:$D$110,2,FALSE) -> 23765.17 | E17: 50.000604 | F17: =(D17/200)*E17*B17 -> 5941.3642 | G17: 30 | H17: RPA | I17: 0.2 | J17: =F17*G17*(1+I17) -> 213889.11 | K17: 31500 | L17: =IF(H19="bolsa",B19,"-") -> 9 | M17: =IF(H19<>"bolsa",B19,"-") -> -
A18: Administrador | B18: 1 | C18: P8175 | D18: =VLOOKUP(C18,'[3]Tabela DNIT Janeiro_2026'!$C$3:$D$110,2,FALSE) -> 8887.1 | E18: 100 | F18: =(D18/200)*E18*B18 -> 4443.55 | G18: 30 | H18: CLT | I18: 0.8404 | J18: =F18*G18*(1+I18) -> 245337.28 | K18: 6079281.8 | L18: =SUM(L3:L17) -> 23 | M18: =SUM(M3:M17) -> 10
A19: Bolsista de Graduação | B19: 9 | C19: BG20 | D19: =VLOOKUP(C19,'[3]Tabela DNIT Janeiro_2026'!$C$3:$D$110,2,FALSE) -> 1050 | E19: 100 | F19: =(D19/200)*E19*B19 -> 4725 | G19: 30 | H19: Bolsa | I19: 0 | J19: =F19*G19*(1+I19) -> 141750
A20: Total do item (R$) | J20: =SUM(J3:J19) -> 4970099.6
A22: Serviços de Terceiros | G22: Qtde | H22: Valor | I22: Encargos | J22: Total (R$)
A23: Contratação de serviço de assessoramento especializada satélites | G23: 1 | H23: 1100000 | I23: 0 | J23: =G23*H23*(1+I23) -> 1100000
A24: Contratação de obtenção de dados satelitais | G24: 5 | H24: 200000 | I24: 0 | J24: =G24*H24*(1+I24) -> 1000000 | L24: (potencial de corrosão: 1500 x 5(OAE) x 5(furos) (pilar)(viga)(laje) = 37.500
A25: Contratação de levantamento geométrico e cadastral das OAEs | G25: 5 | H25: 50000 | I25: 0 | J25: =G25*H25*(1+I25) -> 250000 | L25: (orçamento de 2023 - Araranguá)
A26: Serviços de instalação de sensores em 5 OAEs | G26: 5 | H26: =80000+40000 -> 120000 | I26: 0 | J26: =G26*H26*(1+I26) -> 600000
A27: Calibração dos sistemas de monitoramento em 1 OAE (3 caminhões) | G27: 5 | H27: 40914 | I27: 0 | J27: =G27*H27*(1+I27) -> 204570
A28: Serviços de manutenção, locacão, de IA e demais serviços técnicos profissionais | G28: 30 | H28: 4500 | I28: 0 | J28: =G28*H28*(1+I28) -> 135000
A29: Ensaios em testemunhos e não-destrutivos | G29: 5 | H29: 80000 | I29: 0 | J29: =G29*H29*(1+I29) -> 400000 | L29: (satélite antena+mensalidade)
A30: Energia elétrica para transmissão de dados | G30: 5 | H30: 10000 | I30: 0 | J30: =H30*G30 -> 50000
A31: Transmissão de dados | G31: 5 | H31: 3000 | I31: 0 | J31: =H31*G31 -> 15000
A32: Total do item (R$) | J32: =SUM(J23:J29) -> 3689570
L33: (5 OAEs x 2 visitas; 2 pessoas = 20 viagens)
A34: Passagens e Despesas com Locomoção | F34: Qtde/Mês | G34: Meses | H34: Unitário | I34: Encargos | J34: Total (R$) | L34: (5 visitas CAN x 3 pessoas) + (1 visita benchmarking JPN x 3 pessoas) = 18 viagens
A35: Passagens Nacionais - aéreas e terrestres | F35: 2 | G35: 10 | H35: 4500 | I35: 0 | J35: =F35*G35*H35 -> 90000
A36: Passagens Internacional - aéreas e terrestres | F36: 3 | G36: 6 | H36: 8000 | I36: 0 | J36: =F36*G36*H36 -> 144000
A37: Total do item (R$) | J37: =SUM(J35:J36) -> 234000
L38: (20 viagens; 3 dias cada; 2 pessoas = 120)
A39: Diárias | F39: Qtde/Mês | G39: Meses | H39: Unitário | I39: Encargos | J39: Total (R$) | L39: (18 viagens; 4 dias; 3 pessoas = 216)
A40: Despesas com hospedagem e alimentação (nacional) | F40: 6 | G40: 20 | H40: 668.06 | I40: 0 | J40: =F40*G40*H40 -> 80167.2
A41: Despesas com hospedagem e alimentação (internacional) | F41: 12 | G41: 18 | H41: 2500 | I41: 0 | J41: =F41*G41*H41 -> 540000
...

Sheet Orçamento-Ação2
B1: Qtde | C1: DNIT - jan 26 | E1: Carga Horária Mensal | F1: Valor Mensal | G1: Meses | H1: Vínculo | I1: Encargos | J1: Total (R$)
C2: Ref. | D2: Valor (R$) | K2: 60000 | L2: UFSC | M2: Externo | N2: adm
A3: Coordenador do Termo de Execução Descentralizada | B3: 1 | C3: BC | D3: =VLOOKUP(C3,'[3]Tabela DNIT Janeiro_2026'!$C$3:$D$110,2,FALSE) -> 5000 | E3: 5 | F3: =(D3)*B3/2 -> 2500 | G3: 60 | H3: Bolsa | I3: 0 | J3: =F3*G3*(1+I3) -> 150000 | K3: 160492.92 | L3: =IF(H3="bolsa",B3,"-") -> 1 | M3: =IF(H3<>"bolsa",B3,"-") -> - | N3: =(#REF!+J14+#REF!)/J67 -> #REF!
A4: Engenheiro Coordenador | B4: 1 | C4: P8061 | D4: =VLOOKUP(C4,'[3]Tabela DNIT Janeiro_2026'!$C$3:$D$110,2,FALSE) -> 19804.31 | E4: 50 | F4: =(D4/200)*E4*B4 -> 4951.0775 | G4: 60 | H4: CLT | I4: 0.8404 | J4: =F4*G4*(1+I4) -> 546717.78 | K4: 374392.79 | L4: =IF(H4="bolsa",B4,"-") -> - | M4: =IF(H4<>"bolsa",B4,"-") -> 1
A5: Engenheiro Técnico Responsável (civil) | B5: 1 | C5: P8067 | D5: =VLOOKUP(C5,'[3]Tabela DNIT Janeiro_2026'!$C$3:$D$110,2,FALSE) -> 17274.58 | E5: 100 | F5: =(D5/200)*E5*B5 -> 8637.29 | G5: 30 | H5: CLT | I5: 0.8404 | J5: =F5*G5*(1+I5) -> 476882.06 | K5: 374392.79 | L5: =IF(H5="bolsa",B5,"-") -> - | M5: =IF(H5<>"bolsa",B5,"-") -> 1
A6: Engenheiro de Projetos sênior (civil) | B6: 1 | C6: P8067 | D6: =VLOOKUP(C6,'[3]Tabela DNIT Janeiro_2026'!$C$3:$D$110,2,FALSE) -> 17274.58 | E6: 200 | F6: =(D6/200)*E6*B6 -> 17274.58 | G6: 30 | H6: CLT | I6: 0.8404 | J6: =F6*G6*(1+I6) -> 953764.11 | K6: 412220.63 | L6: =IF(H6="bolsa",B6,"-") -> - | M6: =IF(H6<>"bolsa",B6,"-") -> 1
A7: Engenheiro de Projetos junior (civil) | B7: 1 | C7: P8065 | D7: =VLOOKUP(C7,'[3]Tabela DNIT Janeiro_2026'!$C$3:$D$110,2,FALSE) -> 12443.57 | E7: 100 | F7: =(D7/200)*E7*B7 -> 6221.785 | G7: 60 | H7: CLT | I7: 0.8404 | J7: =F7*G7*(1+I7) -> 687034.39 | K7: 127569.9 | L7: =IF(H7="bolsa",B7,"-") -> - | M7: =IF(H7<>"bolsa",B7,"-") -> 1
A8: Analista de Desenvolvimento de Sistemas Júnior | B8: 1 | C8: P8007 | D8: =VLOOKUP(C8,'[3]Tabela DNIT Janeiro_2026'!$C$3:$D$110,2,FALSE) -> 4278.65 | E8: 100 | F8: =(D8/200)*E8*B8 -> 2139.325 | G8: 30 | H8: CLT | I8: 0.8404 | J8: =F8*G8*(1+I8) -> 118116.41 | K8: 288000 | L8: =IF(H8="bolsa",B8,"-") -> - | M8: =IF(H8<>"bolsa",B8,"-") -> 1
A9: Analista de Banco de Dados | B9: 1 | C9: P8009 | D9: =VLOOKUP(C9,'[3]Tabela DNIT Janeiro_2026'!$C$3:$D$110,2,FALSE) -> 10201.29 | E9: 100 | F9: =(D9/200)*E9*B9 -> 5100.645 | G9: 30 | H9: CLT | I9: 0.8404 | J9: =F9*G9*(1+I9) -> 281616.81 | K9: 151200 | L9: =IF(H10="bolsa",B10,"-") -> 1 | M9: =IF(H10<>"bolsa",B10,"-") -> -
A10: Bolsa de Professor | B10: 1 | C10: BP | D10: =VLOOKUP(C10,'[3]Tabela DNIT Janeiro_2026'!$C$3:$D$110,2,FALSE) -> 3000 | E10: 100 | F10: =(D10/100)*E10*B10 -> 3000 | G10: 60 | H10: Bolsa | I10: 0 | J10: =F10*G10*(1+I10) -> 180000 | K10: 105600 | L10: =IF(H11="bolsa",B11,"-") -> 4 | M10: =IF(H11<>"bolsa",B11,"-") -> -
A11: Bolsista de Graduação | B11: 4 | C11: BG20 | D11: =VLOOKUP(C11,'[3]Tabela DNIT Janeiro_2026'!$C$3:$D$110,2,FALSE) -> 1050 | E11: 100 | F11: =(D11/100)*E11*B11 -> 4200 | G11: 60 | H11: Bolsa | I11: 0 | J11: =F11*G11*(1+I11) -> 252000 | K11: 59939.251 | L11: =IF(H12="bolsa",B12,"-") -> 1 | M11: =IF(H12<>"bolsa",B12,"-") -> -
A12: Bolsista de Mestrado | B12: 1 | C12: BM20 | D12: =VLOOKUP(C12,'[3]Tabela DNIT Janeiro_2026'!$C$3:$D$110,2,FALSE) -> 2200 | E12: 100 | F12: =(D12/100)*E12*B12 -> 2200 | G12: 60 | H12: Bolsa | I12: 0 | J12: =F12*G12*(1+I12) -> 132000 | K12: 191144.83 | L12: =IF(H13="bolsa",B13,"-") -> - | M12: =IF(H13<>"bolsa",B13,"-") -> 1
A13: Redator/Revisor técnico | B13: 1 | C13: P8131 | D13: =VLOOKUP(C13,'[3]Tabela DNIT Janeiro_2026'!$C$3:$D$110,2,FALSE) -> 4110.73 | E13: 50 | F13: =(D13/200)*E13 -> 1027.6825 | G13: 30 | H13: CLT | I13: 0.8404 | J13: =F13*G13*(1+I13) -> 56740.406 | K13: 31500 | L13: =IF(H14="bolsa",B14,"-") -> 4 | M13: =IF(H14<>"bolsa",B14,"-") -> -
A14: Bolsista de Graduação | B14: 4 | C14: BG20 | D14: =VLOOKUP(C14,'[3]Tabela DNIT Janeiro_2026'!$C$3:$D$110,2,FALSE) -> 1050 | E14: 100 | F14: =(D14/100)*E14 -> 1050 | G14: 60 | H14: Bolsa | I14: 0 | J14: =F14*G14*(1+I14) -> 63000 | L14: =SUM(L3:L13) -> 11 | M14: =SUM(M3:M13) -> 6 | N14: =L14+M14 -> 17
A15: Total do item (R$) | J15: =SUM(J3:J14) -> 3897872 | N15: =L15+M15 -> 0
L16: =L14/$N$14*100 -> 64.705882 | M16: =M14/$N$14*100 -> 35.294118 | N16: =L16+M16 -> 100
A17: Serviços de Terceiros | G17: Qtde | H17: Valor | I17: Encargos | J17: Total (R$)
A18: Licenças de software/APIs | G18: 10 | H18: 5000 | I18: 0 | J18: =G18*H18*(1+I18) -> 50000
A19: Manutenção de Equipamentos | G19: 60 | H19: 600 | I19: 0 | J19: =G19*H19*(1+I19) -> 36000
A20: Serviços técnicos profissionais | G20: 60 | H20: 600 | I20: 0 | J20: =G20*H20*(1+I20) -> 36000 | L20: =J15+'[3]Orçamento-Ação1'!J20 -> 8867971.5
A21: Locação de veículo para testes em campo | G21: 15 | H21: 250 | I21: 0 | J21: =G21*H21*(1+I21) -> 3750
A22: Total do item (R$) | J22: =SUM(J18:J21) -> 125750
A24: Passagens e Despesas com Locomoção | F24: Qtde/Mês | G24: Meses | H24: Unitário | I24: Encargos | J24: Total (R$)
A25: Passagens Nacionais - aéreas e terrestres | F25: 0 | G25: 0 | H25: 0 | I25: 0 | J25: =F25*G25*H25 -> 0
A26: Passagens Internacional - aéreas e terrestres | F26: 0 | G26: 0 | H26: 0 | I26: 0 | J26: =F26*G26*H26 -> 0
A27: Total do item (R$) | J27: =SUM(J25:J26) -> 0
A29: Diárias | F29: Qtde/Mês | G29: Meses | H29: Unitário | I29: Encargos | J29: Total (R$) | L29: (20 viagens; 3 dias cada; 2 pessoas = 120)
A30: Despesas com hospedagem e alimentação (nacional) | F30: 6 | G30: 20 | H30: 668.06 | I30: 0 | J30: =F30*G30*H30 -> 80167.2 | L30: (18 viagens; 4 dias; 3 pessoas = 216)
A31: Despesas com hospedagem e alimentação (internacional) | F31: 12 | G31: 18 | H31: 2500 | I31: 0 | J31: =F31*G31*H31 -> 540000
A32: Total do item (R$) | J32: =SUM(J30:J31) -> 620167.2
A34: Material de Consumo | G34: Meses | H34: Mensal | I34: Encargos | J34: Total (R$)
A35: Material de expediente, consumo e insumos de infomática | G35: 60 | H35: 2500 | I35: 0 | J35: =G35*H35*(1+I35) -> 150000
A36: Total do item (R$) | J36: =SUM(J35) -> 150000
A38: Equipamentos | G38: Qtde | H38: Valor | I38: Encargos | J38: Total (R$)
A39: Sensores e aquisitor (OAE de laje contínua c/ strain gauges, acelerômetro, termopar - fibra óptica) | G39: 1 | H39: 443979.98 | I39: 0 | J39: =H39*G39 -> 443979.98
A40: Sensores e aquisitor (OAE em grelha biapoiada c/ strain gauges, termopar) | G40: 2 | H40: 331130.31 | I40: 0 | J40: =H40*G40 -> 662260.62
A41: Sensores e aquisitor (OAE com vãos contínuos c/ strain gauges, termopar) | G41: 1 | H41: 463017.01 | I41: 0 | J41: =H41*G41 -> 463017.01
A42: Sensores e aquisitor (OAE seção caixão c/ strain gauges, termopar) | G42: 1 | H42: 300000 | I42: 0 | J42: =H42*G42 -> 300000
A43: Sensores e aquisitor para potencial de corrosão | G43: 5 | H43: 100000 | I43: 0 | J43: =H43*G43 -> 500000 | L43: (se monitoramento for contínuo)
A44: Gabinetes antivandalismo e comunicação/armazenamento de dados | G44: 5 | H44: 17589 | I44: 0 | J44: =H44*G44 -> 87945
...

Sheet Orçamento Ação 3
A1: Equipe Técnica — Ação 4 (orçamento presumido) | B1: Qtde | C1: DNIT - jul 25 | E1: Carga Horária Mensal | F1: Valor Mensal | G1: Meses | H1: Vínculo | I1: Encargos | J1: Total (R$) | K1: PREMISSAS DO CENÁRIO-BASE
C2: Ref. | D2: Valor (R$) | K2: Estimativa paramétrica adicional; não altera o orçamento vigente sem aprovação e ajuste formal.
A3: Coordenador do Termo de Execução Descentralizada | B3: 1 | C3: BC | D3: 5000 | E3: 5 | F3: =IF(H3="Bolsa",B3*D3,B3*(D3/200)*E3) -> 5000 | G3: 24 | H3: Bolsa | I3: 0 | J3: =F3*G3*(1+I3) -> 120000 | K3: Cenário: uma OAE-piloto, com até quatro faixas/acessos e integração a um CCO.
A4: Engenheiro coordenador da Ação 4 | B4: 1 | C4: P8061 | D4: 19378.99 | E4: 50 | F4: =IF(H4="Bolsa",B4*D4,B4*(D4/200)*E4) -> 4844.7475 | G4: 24 | H4: CLT | I4: 0.8404 | J4: =F4*G4*(1+I4) -> 213990.56 | K4: HSWIM somente se as atividades 4A4 e 4A5 confirmarem necessidade e viabilidade.
A5: Engenheiro responsável técnico estrutural | B5: 1 | C5: P8067 | D5: 16952.51 | E5: 60 | F5: =IF(H5="Bolsa",B5*D5,B5*(D5/200)*E5) -> 5085.753 | G5: 24 | H5: CLT | I5: 0.8404 | J5: =F5*G5*(1+I5) -> 224635.68 | K5: Rubricas, encargos e percentuais seguem as abas Orçamento e Consolidado do arquivo de referência.
A6: Engenheiro de tráfego e operação rodoviária | B6: 1 | C6: P8067 | D6: 16952.51 | E6: 60 | F6: =IF(H6="Bolsa",B6*D6,B6*(D6/200)*E6) -> 5085.753 | G6: 24 | H6: CLT | I6: 0.8404 | J6: =F6*G6*(1+I6) -> 224635.68 | K6: Valores da equipe usam as referências DNIT de julho/2025 constantes do arquivo fornecido.
A7: Engenheiro de automação, energia e sistemas | B7: 1 | C7: P8066 | D7: 14698.04 | E7: 60 | F7: =IF(H7="Bolsa",B7*D7,B7*(D7/200)*E7) -> 4409.412 | G7: 24 | H7: CLT | I7: 0.8404 | J7: =F7*G7*(1+I7) -> 194761.96
A8: Engenheiro de projetos civis e sinalização | B8: 1 | C8: P8066 | D8: 14698.04 | E8: 50 | F8: =IF(H8="Bolsa",B8*D8,B8*(D8/200)*E8) -> 3674.51 | G8: 24 | H8: CLT | I8: 0.8404 | J8: =F8*G8*(1+I8) -> 162301.64 | K8: Rubrica | L8: Valor (R$) | M8: % da Ação 4
A9: Especialista sênior em HSWIM e metrologia | B9: 1 | C9: P8060 | D9: 23254.78 | E9: 40 | F9: =IF(H9="Bolsa",B9*D9,B9*(D9/200)*E9) -> 4650.956 | G9: 24 | H9: RPA | I9: 0.2 | J9: =F9*G9*(1+I9) -> 133947.53 | K9: Equipe Técnica | L9: =J19 -> 2086949.6 | M9: =L9/$L$17 -> 0.2390436
A10: Analista sênior de sistemas e integração | B10: 1 | C10: P8009 | D10: 10184.53 | E10: 50 | F10: =IF(H10="Bolsa",B10*D10,B10*(D10/200)*E10) -> 2546.1325 | G10: 24 | H10: CLT | I10: 0.8404 | J10: =F10*G10*(1+I10) -> 112461.65 | K10: Serviços de Terceiros | L10: =J25 -> 1120000 | M10: =L10/$L$17 -> 0.12828716
A11: Analista de sistemas, dados e painéis | B11: 1 | C11: P8008 | D11: 5705.05 | E11: 80 | F11: =IF(H11="Bolsa",B11*D11,B11*(D11/200)*E11) -> 2282.02 | G11: 24 | H11: CLT | I11: 0.8404 | J11: =F11*G11*(1+I11) -> 100795.91 | K11: Passagens e Locomoção | L11: =J30 -> 258000 | M11: =L11/$L$17 -> 0.029551863
A12: Especialista em dados e cibersegurança | B12: 1 | C12: P8009 | D12: 10184.53 | E12: 50 | F12: =IF(H12="Bolsa",B12*D12,B12*(D12/200)*E12) -> 2546.1325 | G12: 24 | H12: CLT | I12: 0.8404 | J12: =F12*G12*(1+I12) -> 112461.65 | K12: Diárias | L12: =J35 -> 128267.52 | M12: =L12/$L$17 -> 0.014692032
A13: Técnico de obras e instalações | B13: 1 | C13: P8147 | D13: 3323.33 | E13: 120 | F13: =IF(H13="Bolsa",B13*D13,B13*(D13/200)*E13) -> 1993.998 | G13: 24 | H13: CLT | I13: 0.8404 | J13: =F13*G13*(1+I13) -> 88074.094 | K13: Material de Consumo | L13: =J39 -> 72000 | M13: =L13/$L$17 -> 0.0082470316
A14: Técnico de segurança do trabalho | B14: 1 | C14: P8151 | D14: 4601.83 | E14: 40 | F14: =IF(H14="Bolsa",B14*D14,B14*(D14/200)*E14) -> 920.366 | G14: 24 | H14: CLT | I14: 0.8404 | J14: =F14*G14*(1+I14) -> 40652.198 | K14: Equipamentos | L14: =J54 -> 3760000 | M14: =L14/$L$17 -> 0.43067832
A15: Administrador sênior | B15: 1 | C15: P8175 | D15: 8655.04 | E15: 50 | F15: =IF(H15="Bolsa",B15*D15,B15*(D15/200)*E15) -> 2163.76 | G15: 24 | H15: CLT | I15: 0.8404 | J15: =F15*G15*(1+I15) -> 95572.414 | K15: Ressarcimentos Fundação de Apoio | L15: =J64 -> 694067.91 | M15: =L15/$L$17 -> 0.0795
A16: Assessoria técnica independente e revisão | B16: 1 | C16: P8060 | D16: 23254.78 | E16: 25 | F16: =IF(H16="Bolsa",B16*D16,B16*(D16/200)*E16) -> 2906.8475 | G16: 12 | H16: RPA | I16: 0.2 | J16: =F16*G16*(1+I16) -> 41858.604 | K16: Ressarcimentos UFSC | L16: =J68 -> 611128.98 | M16: =L16/$L$17 -> 0.07
A17: Bolsista de mestrado | B17: 2 | C17: BM20 | D17: 2200 | E17: 100 | F17: =IF(H17="Bolsa",B17*D17,B17*(D17/200)*E17) -> 4400 | G17: 24 | H17: Bolsa | I17: 0 | J17: =F17*G17*(1+I17) -> 105600 | K17: Total da Ação 4 | L17: =SUM(L9:L16) -> 8730414 | M17: =SUM(M9:M16) -> 1
A18: Bolsista de doutorado | B18: 1 | C18: BD20 | D18: 3200 | E18: 100 | F18: =IF(H18="Bolsa",B18*D18,B18*(D18/200)*E18) -> 3200 | G18: 36 | H18: Bolsa | I18: 0 | J18: =F18*G18*(1+I18) -> 115200
A19: Total do item (R$) | J19: =SUM(J3:J18) -> 2086949.6
A21: Serviços de Terceiros | G21: Qtde | H21: Valor | I21: Encargos | J21: Total (R$)
A22: Estudos de tráfego, carga passante e necessidade de dados | G22: 1 | H22: 220000 | I22: 0 | J22: =G22*H22*(1+I22) -> 220000
A23: Instalação e integração dos equipamentos de campo | G23: 1 | H23: 450000 | I23: 0 | J23: =G23*H23*(1+I23) -> 450000
A24: Calibração, comissionamento, FAT/SAT, simulados e capacitação | G24: 1 | H24: 450000 | I24: 0 | J24: =G24*H24*(1+I24) -> 450000
A25: Total do item (R$) | J25: =SUM(J22:J24) -> 1120000
A27: Passagens e Despesas com Locomoção | F27: Qtde/Mês | G27: Meses | H27: Unitário | I27: Encargos | J27: Total (R$)
A28: Passagens nacionais — equipes de campo e reuniões técnicas | F28: 2 | G28: 18 | H28: 4500 | I28: 0 | J28: =F28*G28*H28*(1+I28) -> 162000
A29: Transporte terrestre especializado e mobilização de equipamentos | F29: 1 | G29: 12 | H29: 8000 | I29: 0 | J29: =F29*G29*H29*(1+I29) -> 96000
A30: Total do item (R$) | J30: =SUM(J28:J29) -> 258000
A32: Diárias | F32: Qtde/Mês | G32: Meses | H32: Unitário | I32: Encargos | J32: Total (R$)
A33: Hospedagem e alimentação — levantamentos, implantação e testes | F33: 6 | G33: 20 | H33: 668.06 | I33: 0 | J33: =F33*G33*H33*(1+I33) -> 80167.2
A34: Diárias para simulados, operação noturna e contingências | F34: 4 | G34: 18 | H34: 668.06 | I34: 0 | J34: =F34*G34*H34*(1+I34) -> 48100.32
A35: Total do item (R$) | J35: =SUM(J33:J34) -> 128267.52
A37: Material de Consumo | G37: Meses | H37: Mensal | I37: Encargos | J37: Total (R$)
A38: Materiais de campo, sinalização provisória, cabos, conectores e insumos | G38: 48 | H38: 1500 | I38: 0 | J38: =G38*H38*(1+I38) -> 72000
A39: Total do item (R$) | J39: =SUM(J38:J38) -> 72000
A41: Equipamentos | G41: Qtde | H41: Valor | I41: Encargos | J41: Total (R$)
A42: Sistema HSWIM completo para até quatro faixas, quando tecnicamente indicado | G42: 1 | H42: 1200000 | I42: 0 | J42: =G42*H42*(1+I42) -> 1200000
A43: Painéis de mensagem variável com controladores e comunicação | G43: 4 | H43: 140000 | I43: 0 | J43: =G43*H43*(1+I43) -> 560000
A44: Câmeras IP/analíticas para aproximações, tabuleiro e dispositivos | G44: 12 | H44: 15000 | I44: 0 | J44: =G44*H44*(1+I44) -> 180000
A45: Barreiras/cancelas com intertravamentos e liberação de emergência | G45: 4 | H45: 90000 | I45: 0 | J45: =G45*H45*(1+I45) -> 360000
...

Sheet Consolidado
A1: N° | B1: Item de Despesa | C1: Valor da Ação 1 | D1: Valor da Ação 2 | E1: Valor da Ação 3 | F1: Valor Total
A2: 1 | B2: Equipe Técnica | C2: ='Orçamento-Ação1'!J20 -> 4970099.6 | D2: ='Orçamento-Ação2'!J15 -> 3897872 | E2: ='Orçamento Ação 3'!J19 -> 2086949.6 | F2: =SUM(C2:E2) -> 10954921 | G2: =F2/$F$10 -> 0.34682444
A3: =A2+1 -> 2 | B3: Serviços de Terceiros | C3: ='Orçamento-Ação1'!J32 -> 3689570 | D3: ='Orçamento-Ação2'!J22 -> 125750 | E3: ='Orçamento Ação 3'!J25 -> 1120000 | F3: =SUM(C3:E3) -> 4935320 | G3: =F3/$F$10 -> 0.15624846
A4: =A3+1 -> 3 | B4: Passagens e Despesas com Locomoção | C4: ='Orçamento-Ação1'!J37 -> 234000 | D4: ='Orçamento-Ação2'!J27 -> 0 | E4: ='Orçamento Ação 3'!J30 -> 258000 | F4: =SUM(C4:E4) -> 492000 | G4: =F4/$F$10 -> 0.015576344
A5: =A4+1 -> 4 | B5: Diárias | C5: ='Orçamento-Ação1'!J42 -> 620167.2 | D5: ='Orçamento-Ação2'!J32 -> 620167.2 | E5: ='Orçamento Ação 3'!J35 -> 128267.52 | F5: =SUM(C5:E5) -> 1368601.9 | G5: =F5/$F$10 -> 0.043328892
A6: =A5+1 -> 5 | B6: Material de Consumo | C6: ='Orçamento-Ação1'!J46 -> 75000 | D6: ='Orçamento-Ação2'!J36 -> 150000 | E6: ='Orçamento Ação 3'!J39 -> 72000 | F6: =SUM(C6:E6) -> 297000 | G6: =F6/$F$10 -> 0.0094027932
A7: =A6+1 -> 6 | B7: Equipamentos | C7: ='Orçamento-Ação1'!J61 -> 2528177.6 | D7: ='Orçamento-Ação2'!J51 -> 2528177.6 | E7: ='Orçamento Ação 3'!J54 -> 3760000 | F7: =SUM(C7:E7) -> 8816355.2 | G7: =F7/$F$10 -> 0.27911907
A8: =A7+1 -> 7 | B8: Ressarcimentos Fundação de Apoio | C8: ='Orçamento-Ação1'!J71 -> 1132631 | D8: ='Orçamento-Ação2'!J61 -> 684416.65 | E8: ='Orçamento Ação 3'!J64 -> 694067.91 | F8: =SUM(C8:E8) -> 2511115.5 | G8: =F8/$F$10 -> 0.0795
A9: =A8+1 -> 8 | B9: Ressarcimentos UFSC | C9: ='Orçamento-Ação1'!J75 -> 997285.13 | D9: ='Orçamento-Ação2'!J65 -> 602631.01 | E9: ='Orçamento Ação 3'!J68 -> 611128.98 | F9: =SUM(C9:E9) -> 2211045.1 | G9: =F9/$F$10 -> 0.07
A10: Totais (R$) | C10: =SUM(C2:C9) -> 14246930 | D10: =SUM(D2:D9) -> 8609014.4 | E10: =SUM(E2:E9) -> 8730414 | F10: =SUM(F2:F9) -> 31586359 | G10: =F10/$F$10 -> 1
A12: N° | B12: Cronograma de Desembolso | C12: Total (R$)
A13: 1 | B13: Até 10 dias após assinatura do Termo de Execuçaõ descentralizada | C13: =($F$10*D13) -> 4737953.8 | D13: 0.15
A14: =A13+1 -> 2 | B14: Mediante aprovalção e entrega do relatório 1 - R1 | C14: =($F$10*D14) -> 4737953.8 | D14: 0.15
A15: =A14+1 -> 3 | B15: Mediante aprovalção e entrega do relatório 2 - R2 | C15: =($F$10*D15) -> 3158635.9 | D15: 0.1
A16: =A15+1 -> 4 | B16: Mediante aprovalção e entrega do relatório 3 - R3 | C16: =($F$10*D16) -> 3158635.9 | D16: 0.1
A17: =A16+1 -> 5 | B17: Mediante aprovalção e entrega do relatório 4 - R4 | C17: =($F$10*D17) -> 3158635.9 | D17: 0.1
A18: =A17+1 -> 6 | B18: Mediante aprovalção e entrega do relatório 5 - R5 | C18: =($F$10*D18) -> 3158635.9 | D18: 0.1
A19: =A18+1 -> 7 | B19: Mediante aprovalção e entrega do relatório 6 - R6 | C19: =($F$10*D19) -> 3158635.9 | D19: 0.1
A20: =A19+1 -> 8 | B20: Mediante aprovalção e entrega do relatório 7 - R7 | C20: =($F$10*D20) -> 3158635.9 | D20: 0.1
A21: =A20+1 -> 9 | B21: Mediante aprovalção e entrega do relatório 8 - R8 | C21: =($F$10*D21) -> 3158635.9 | D21: 0.1
A22: Valor total (R$) | C22: =SUM(C13:C21) -> 31586359 | D22: =SUM(D13:D21) -> 1

Sheet Cronograma
A1: AÇÕES / METAS / ATIVIDADES / PRODUTOS | C1: 2026 | G1: 2027 | S1: 2028 | AE1: 2029 | AQ1: 2030 | BC1: 2031
C2: 46280 | D2: 46310 | E2: 46341 | F2: 46371 | G2: 46402 | H2: 46433 | I2: 46461 | J2: 46492 | K2: 46522 | L2: 46553 | M2: 46583 | N2: 46614 | O2: 46645 | P2: 46675 | Q2: 46706 | R2: 46736 | S2: 46767 | T2: 46798 | U2: 46827 | V2: 46858 | W2: 46888 | X2: 46919 | Y2: 46949 | Z2: 46980 | AA2: 47011 | AB2: 47041 | AC2: 47072 | AD2: 47102 | AE2: 47133 | AF2: 47164 | AG2: 47192 | AH2: 47223 | AI2: 47253 | AJ2: 47284 | AK2: 47314 | AL2: 47345 | AM2: 47376 | AN2: 47406 | AO2: 47437 | AP2: 47467 | AQ2: 47498 | AR2: 47529 | AS2: 47557 | AT2: 47588 | AU2: 47618 | AV2: 47649 | AW2: 47679 | AX2: 47710 | AY2: 47741 | AZ2: 47771 | BA2: 47802 | BB2: 47832 | BC2: 47863 | BD2: 47894 | BE2: 47922 | BF2: 47953 | BG2: 47983 | BH2: 48014 | BI2: 48044 | BJ2: 48075
A3: 1 | B3: Instrumentação e Diagnóstico do Ciclo Completo de Monitoramento das OAEs | BK3: 5 OAEs
A4: Meta 1A - Definir tecnologias, métodos e procedimentos para avaliação e monitoramento de OAE com foco em SHM
A5: 1A1 | B5: Identificação de parâmetros de monitoramento da saúde estrutural de OAEs
A6: 1A2 | B6: Identificação dos tipos de sensores e métodos de ensaios
A7: Produto 1A.1 - Estudo do estado da arte e da prática sobre Structural Health Monitoring (SHM) aplicado a Obras de Arte Especiais, incluindo diretrizes técnicas preliminares para a definição de parâmetros, seleção de sensores e métodos de monitoramento
A8: Meta 1B - Monitorar e avaliar a estrutura de OAEs por sensores e satélites
A9: 1B1 | B9: Identificação de cinco OAEs para coleta de dados com sensores e satélites
A10: 1B2 | B10: Contratação de levantamento geométrico e cadastral das OAEs
A11: 1B3 | B11: Elaboração de projeto de instrumentação e inspeção das OAEs
A12: 1B4 | B12: Aquisição de equipamentos e contratação de serviços de monitoramento por satélite
A13: 1B5 | B13: Instalação de sistema de instrumentação de OAEs e realização de ensaios do concreto
A14: 1B6 | B14: Calibração e homologação do sistema instalado
A15: 1B7 | B15: Elaboração de modelos de análise estrutural de OAEs
A16: 1B8 | B16: Integração de dados experimentais utilizando gêmeos digitais
A17: 1B9 | B17: Realização de estudos e análises baseadas em dados (com IA) para a interpretação do ciclo completo de monitoramento
A18: 1B10 | B18: Apoio na elaboração de normas e diretrizes para instrumentação e monitoramento de OAEs
A19: 1B11 | B19: Desenvolvimento de ferramenta para integração e diagnóstico de dados
A20: 1B12 | B20: Treinamento e apoio na interpretação dos dados de monitoramento de OAEs
A21: Produto 1B1 - Metodologia de Instrumentação de sensores para monitoramento de OAEs
A22: Produto 1B2 - Metodologia de aquisição de dados por satélites para monitoramento de OAEs
A23: Produto 1B3 - Projeto de instrumentação das OAEs
A24: Produto 1B4 - Base de dados dos sensores para monitoramento de OAEs
A25: Produto 1B5 - Modelos numéricos e gêmeos digitais para interpretação de dados de monitoramento de OAEs
A26: Produto 1B6 - Minuta de normas para instrumentação e monitoramento de OAEs
A27: Produto 1B7 - Ferramenta computacional de monitoramento de OAEs
A28: Produto 1B8 - Treinamento da ferramenta computacional de monitoramento de OAEs
A29: 2 | B29: Suporte à Análise dos Relatórios Encaminhados pelo DNIT | BK29: 100 OAEs
A30: Meta 2A - Avaliar as informações sobre monitoramento de OAEs das empresas contratadas pela DIR
A31: 2A1 | B31: Estudo dos dados e relatórios técnicos relacionados ao monitoramento de OAEs da DIR
A32: 2A2 | B32: Comparação entre as informações dos relatórios de monitoramento e capacidade estrutural das OAEs
A33: Produto 2A1 - Compatibilização da avalição da capacidade estrutural das OAEs | BK33: 10 Produtos | BL33: 10 projetos por Produto
A34: Meta 2B - Apoiar o acompanhamento, a integração e o aprimoramento da análise e interpretação de dados de monitoramento
A35: 2B1 | B35: Compatibilização das metodologias de monitoramento de OAE
A36: 2B2 | B36: Identificação dos processos para o monitoramento de OAEs
A37: 2B3 | B37: Consolidação da ferramenta computacional
A38: 2B4 | B38: Treinamento e apoio na interpretação dos dados de monitoramento de OAEs
A39: Produto 2B1 - Relatório técnico de identificação de melhorias nos processos de análise e interpretação de dados
A40: Produto 2B2 - Elaboração do Plano de Monitoramento de OAE
...
